Workbook

Sheet sales_data
A1: Product_ID | B1: Sale_Date | C1: Sales_Rep | D1: Region | E1: Sales_Amount | F1: Quantity_Sold | G1: Product_Category | H1: Unit_Cost | I1: Unit_Price | J1: Customer_Type | K1: Discount | L1: Payment_Method | M1: Sales_Channel | N1: Region_and_Sales_Rep | O1: Order Flag
A2: 1052 | B2: 44960 | C2: Bob | D2: North | E2: 5053.97 | F2: 18 | G2: Furniture | H2: 152.75 | I2: 267.22 | J2: Returning | K2: 0.09 | L2: Cash | M2: Online | N2: North-Bob | O2: =IF(E2>AVERAGE($E$2:$E$1001),"High","Low") -> High
A3: 1093 | B3: 45037 | C3: Bob | D3: West | E3: 4384.02 | F3: 17 | G3: Furniture | H3: 3816.39 | I3: 4209.44 | J3: Returning | K3: 0.11 | L3: Cash | M3: Retail | N3: West-Bob | O3: =IF(E3>AVERAGE($E$2:$E$1001),"High","Low") -> Low
A4: 1015 | B4: 45190 | C4: David | D4: South | E4: 4631.23 | F4: 30 | G4: Food | H4: 261.56 | I4: 371.4 | J4: Returning | K4: 0.2 | L4: Bank Transfer | M4: Retail | N4: South-David | O4: =IF(E4>AVERAGE($E$2:$E$1001),"High","Low") -> Low
A5: 1072 | B5: 45162 | C5: Bob | D5: South | E5: 2167.94 | F5: 39 | G5: Clothing | H5: 4330.03 | I5: 4467.75 | J5: New | K5: 0.02 | L5: Credit Card | M5: Retail | N5: South-Bob | O5: =IF(E5>AVERAGE($E$2:$E$1001),"High","Low") -> Low
A6: 1061 | B6: 45009 | C6: Charlie | D6: East | E6: 3750.2 | F6: 13 | G6: Electronics | H6: 637.37 | I6: 692.71 | J6: New | K6: 0.08 | L6: Credit Card | M6: Online | N6: East-Charlie | O6: =IF(E6>AVERAGE($E$2:$E$1001),"High","Low") -> Low
A7: 1021 | B7: 44968 | C7: Charlie | D7: West | E7: 3761.15 | F7: 32 | G7: Food | H7: 900.79 | I7: 1106.51 | J7: New | K7: 0.21 | L7: Cash | M7: Online | N7: West-Charlie | O7: =IF(E7>AVERAGE($E$2:$E$1001),"High","Low") -> Low
A8: 1083 | B8: 45027 | C8: Bob | D8: West | E8: 618.31 | F8: 29 | G8: Furniture | H8: 2408.81 | I8: 2624.09 | J8: Returning | K8: 0.14 | L8: Cash | M8: Online | N8: West-Bob | O8: =IF(E8>AVERAGE($E$2:$E$1001),"High","Low") -> Low
A9: 1087 | B9: 44932 | C9: Eve | D9: South | E9: 7698.92 | F9: 46 | G9: Furniture | H9: 3702.51 | I9: 3964.65 | J9: New | K9: 0.12 | L9: Bank Transfer | M9: Online | N9: South-Eve | O9: =IF(E9>AVERAGE($E$2:$E$1001),"High","Low") -> High
A10: 1075 | B10: 45106 | C10: David | D10: South | E10: 4223.39 | F10: 30 | G10: Furniture | H10: 738.06 | I10: 1095.4499999999998 | J10: New | K10: 0.05 | L10: Bank Transfer | M10: Online | N10: South-David | O10: =IF(E10>AVERAGE($E$2:$E$1001),"High","Low") -> Low
A11: 1075 | B11: 45208 | C11: Charlie | D11: West | E11: 8239.58 | F11: 18 | G11: Clothing | H11: 2228.35 | I11: 2682.34 | J11: New | K11: 0.13 | L11: Bank Transfer | M11: Online | N11: West-Charlie | O11: =IF(E11>AVERAGE($E$2:$E$1001),"High","Low") -> High
A12: 1088 | B12: 45246 | C12: Eve | D12: North | E12: 8518.45 | F12: 13 | G12: Furniture | H12: 2440.11 | I12: 2517.6 | J12: New | K12: 0.23 | L12: Bank Transfer | M12: Retail | N12: North-Eve | O12: =IF(E12>AVERAGE($E$2:$E$1001),"High","Low") -> High
A13: 1100 | B13: 45152 | C13: Bob | D13: West | E13: 2198.74 | F13: 43 | G13: Food | H13: 1100.81 | I13: 1137.44 | J13: Returning | K13: 0.08 | L13: Bank Transfer | M13: Online | N13: West-Bob | O13: =IF(E13>AVERAGE($E$2:$E$1001),"High","Low") -> Low
A14: 1024 | B14: 45241 | C14: Eve | D14: West | E14: 6607.8 | F14: 21 | G14: Food | H14: 622.01 | I14: 641.09 | J14: Returning | K14: 0 | L14: Bank Transfer | M14: Retail | N14: West-Eve | O14: =IF(E14>AVERAGE($E$2:$E$1001),"High","Low") -> High
A15: 1003 | B15: 45291 | C15: Alice | D15: South | E15: 4775.59 | F15: 30 | G15: Furniture | H15: 4190.28 | I15: 4270.65 | J15: New | K15: 0.2 | L15: Cash | M15: Online | N15: South-Alice | O15: =IF(E15>AVERAGE($E$2:$E$1001),"High","Low") -> Low
A16: 1022 | B16: 45155 | C16: Charlie | D16: South | E16: 8813.55 | F16: 21 | G16: Food | H16: 2537.2 | I16: 2869.6 | J16: New | K16: 0.29 | L16: Bank Transfer | M16: Retail | N16: South-Charlie | O16: =IF(E16>AVERAGE($E$2:$E$1001),"High","Low") -> High
A17: 1053 | B17: 45215 | C17: Bob | D17: North | E17: 2235.83 | F17: 48 | G17: Furniture | H17: 121.19 | I17: 487.65 | J17: New | K17: 0.18 | L17: Cash | M17: Retail | N17: North-Bob | O17: =IF(E17>AVERAGE($E$2:$E$1001),"High","Low") -> Low
A18: 1002 | B18: 45076 | C18: David | D18: North | E18: 6810.35 | F18: 17 | G18: Furniture | H18: 4024.76 | I18: 4420.150000000001 | J18: Returning | K18: 0.04 | L18: Cash | M18: Online | N18: North-David | O18: =IF(E18>AVERAGE($E$2:$E$1001),"High","Low") -> High
A19: 1088 | B19: 45203 | C19: Bob | D19: East | E19: 6116.75 | F19: 40 | G19: Electronics | H19: 4904.93 | I19: 5034.35 | J19: New | K19: 0.1 | L19: Credit Card | M19: Retail | N19: East-Bob | O19: =IF(E19>AVERAGE($E$2:$E$1001),"High","Low") -> High
A20: 1030 | B20: 45124 | C20: David | D20: West | E20: 3023.48 | F20: 19 | G20: Clothing | H20: 3049.33 | I20: 3209.22 | J20: Returning | K20: 0.26 | L20: Cash | M20: Online | N20: West-David | O20: =IF(E20>AVERAGE($E$2:$E$1001),"High","Low") -> Low
A21: 1038 | B21: 44996 | C21: Bob | D21: South | E21: 1452.35 | F21: 15 | G21: Clothing | H21: 2543.36 | I21: 2790.1000000000004 | J21: Returning | K21: 0.07 | L21: Cash | M21: Online | N21: South-Bob | O21: =IF(E21>AVERAGE($E$2:$E$1001),"High","Low") -> Low
A22: 1002 | B22: 45038 | C22: Eve | D22: North | E22: 6551.23 | F22: 9 | G22: Electronics | H22: 4398.16 | I22: 4439.12 | J22: New | K22: 0.18 | L22: Bank Transfer | M22: Online | N22: North-Eve | O22: =IF(E22>AVERAGE($E$2:$E$1001),"High","Low") -> High
A23: 1064 | B23: 44930 | C23: Eve | D23: East | E23: 7412.11 | F23: 10 | G23: Electronics | H23: 4764.96 | I23: 5074.42 | J23: New | K23: 0.12 | L23: Cash | M23: Online | N23: East-Eve | O23: =IF(E23>AVERAGE($E$2:$E$1001),"High","Low") -> High
A24: 1060 | B24: 45276 | C24: Eve | D24: East | E24: 3224.71 | F24: 44 | G24: Clothing | H24: 3784.96 | I24: 4276.99 | J24: New | K24: 0.06 | L24: Bank Transfer | M24: Retail | N24: East-Eve | O24: =IF(E24>AVERAGE($E$2:$E$1001),"High","Low") -> Low
A25: 1021 | B25: 45257 | C25: Alice | D25: South | E25: 6483.84 | F25: 31 | G25: Furniture | H25: 2254.99 | I25: 2441.79 | J25: Returning | K25: 0.24 | L25: Bank Transfer | M25: Online | N25: South-Alice | O25: =IF(E25>AVERAGE($E$2:$E$1001),"High","Low") -> High
A26: 1033 | B26: 45244 | C26: David | D26: South | E26: 4011.8 | F26: 23 | G26: Furniture | H26: 2981.5 | I26: 3360.4 | J26: Returning | K26: 0.22 | L26: Bank Transfer | M26: Retail | N26: South-David | O26: =IF(E26>AVERAGE($E$2:$E$1001),"High","Low") -> Low
A27: 1076 | B27: 45276 | C27: Eve | D27: East | E27: 7160.75 | F27: 30 | G27: Clothing | H27: 3519.63 | I27: 3774.65 | J27: New | K27: 0.2 | L27: Credit Card | M27: Retail | N27: East-Eve | O27: =IF(E27>AVERAGE($E$2:$E$1001),"High","Low") -> High
A28: 1058 | B28: 45021 | C28: Alice | D28: North | E28: 2072.23 | F28: 33 | G28: Furniture | H28: 1011.65 | I28: 1084.28 | J28: Returning | K28: 0.07 | L28: Bank Transfer | M28: Retail | N28: North-Alice | O28: =IF(E28>AVERAGE($E$2:$E$1001),"High","Low") -> Low
A29: 1022 | B29: 45078 | C29: David | D29: East | E29: 8913.13 | F29: 9 | G29: Electronics | H29: 2263.65 | I29: 2558.9500000000003 | J29: New | K29: 0.03 | L29: Cash | M29: Online | N29: East-David | O29: =IF(E29>AVERAGE($E$2:$E$1001),"High","Low") -> High
A30: 1089 | B30: 45237 | C30: Bob | D30: West | E30: 2945.36 | F30: 47 | G30: Furniture | H30: 4157.62 | I30: 4314.5599999999995 | J30: New | K30: 0.17 | L30: Bank Transfer | M30: Retail | N30: West-Bob | O30: =IF(E30>AVERAGE($E$2:$E$1001),"High","Low") -> Low
A31: 1049 | B31: 45063 | C31: Alice | D31: West | E31: 3741.08 | F31: 1 | G31: Furniture | H31: 3290.89 | I31: 3317.75 | J31: Returning | K31: 0.17 | L31: Bank Transfer | M31: Online | N31: West-Alice | O31: =IF(E31>AVERAGE($E$2:$E$1001),"High","Low") -> Low
A32: 1091 | B32: 45173 | C32: Charlie | D32: South | E32: 675.11 | F32: 44 | G32: Food | H32: 2085.46 | I32: 2406.58 | J32: Returning | K32: 0.06 | L32: Bank Transfer | M32: Retail | N32: South-Charlie | O32: =IF(E32>AVERAGE($E$2:$E$1001),"High","Low") -> Low
A33: 1059 | B33: 45169 | C33: Alice | D33: North | E33: 1203.97 | F33: 35 | G33: Food | H33: 3333.64 | I33: 3764.52 | J33: Returning | K33: 0.02 | L33: Credit Card | M33: Online | N33: North-Alice | O33: =IF(E33>AVERAGE($E$2:$E$1001),"High","Low") -> Low
A34: 1042 | B34: 44957 | C34: Alice | D34: North | E34: 5207.03 | F34: 11 | G34: Food | H34: 635.2 | I34: 814.1400000000001 | J34: Returning | K34: 0.02 | L34: Cash | M34: Online | N34: North-Alice | O34: =IF(E34>AVERAGE($E$2:$E$1001),"High","Low") -> High
A35: 1092 | B35: 44966 | C35: David | D35: West | E35: 2749.17 | F35: 34 | G35: Furniture | H35: 2037.41 | I35: 2238.65 | J35: New | K35: 0.3 | L35: Credit Card | M35: Online | N35: West-David | O35: =IF(E35>AVERAGE($E$2:$E$1001),"High","Low") -> Low
A36: 1060 | B36: 45155 | C36: Bob | D36: East | E36: 8371.25 | F36: 16 | G36: Clothing | H36: 3975.99 | I36: 4422.59 | J36: New | K36: 0.24 | L36: Cash | M36: Online | N36: East-Bob | O36: =IF(E36>AVERAGE($E$2:$E$1001),"High","Low") -> High
A37: 1080 | B37: 44962 | C37: Charlie | D37: South | E37: 245.46 | F37: 9 | G37: Electronics | H37: 1141.52 | I37: 1550.19 | J37: New | K37: 0.28 | L37: Credit Card | M37: Retail | N37: South-Charlie | O37: =IF(E37>AVERAGE($E$2:$E$1001),"High","Low") -> Low
A38: 1015 | B38: 45149 | C38: Eve | D38: East | E38: 3853.03 | F38: 32 | G38: Furniture | H38: 970.51 | I38: 1330.84 | J38: Returning | K38: 0.06 | L38: Cash | M38: Retail | N38: East-Eve | O38: =IF(E38>AVERAGE($E$2:$E$1001),"High","Low") -> Low
A39: 1062 | B39: 44932 | C39: Eve | D39: East | E39: 3439.72 | F39: 15 | G39: Clothing | H39: 4756.55 | I39: 4888.46 | J39: New | K39: 0.29 | L39: Credit Card | M39: Online | N39: East-Eve | O39: =IF(E39>AVERAGE($E$2:$E$1001),"High","Low") -> Low
A40: 1062 | B40: 45248 | C40: Alice | D40: East | E40: 291.34 | F40: 12 | G40: Furniture | H40: 1088.99 | I40: 1545 | J40: Returning | K40: 0.04 | L40: Bank Transfer | M40: Retail | N40: East-Alice | O40: =IF(E40>AVERAGE($E$2:$E$1001),"High","Low") -> Low
...

Sheet Summary
A1: Summary
A3: Total Revenue | B3: =SUM(sales_data!E2:'sales_data'!E1001) -> 5019265.2
A4: Average Order Value | B4: =AVERAGE(sales_data!E2:'sales_data'!E1001) -> 5019.2652
A5: Number of Transactions | B5: =COUNT(sales_data!E2:'sales_data'!E1001) -> 1000
A6: Highest Sale | B6: =MAX(sales_data!E2:'sales_data'!E1001) -> 9989.04
A7: Lowest Sale | B7: =MIN(sales_data!E2:'sales_data'!E1001) -> 100.12
